[2020-03-02 09:21:29 +0100] [2094] [INFO] Starting gunicorn 20.0.4
[2020-03-02 09:21:29 +0100] [2094] [INFO] Listening at: http://127.0.0.1:8000 (2094)
[2020-03-02 09:21:29 +0100] [2094] [INFO] Using worker: sync
[2020-03-02 09:21:29 +0100] [2097] [INFO] Booting worker with pid: 2097
[2020-03-02 09:22:03 +0100] [2094] [INFO] Handling signal: hup
[2020-03-02 09:22:03 +0100] [2094] [INFO] Hang up: Master
[2020-03-02 09:22:03 +0100] [2094] [INFO] Handling signal: term
[2020-03-02 09:22:03 +0100] [2123] [INFO] Booting worker with pid: 2123
[2020-03-02 09:22:05 +0100] [2123] [ERROR] Exception in worker process
Traceback (most recent call last):
  File "/usr/local/lib/python3.6/site-packages/mysql/connector/network.py", line 509, in open_connection
    self.sock.connect(sockaddr)
ConnectionRefusedError: [Errno 111] Connection refused

During handling of the above exception, another exception occurred:

Traceback (most recent call last):
  File "/usr/local/lib/python3.6/site-packages/gunicorn/arbiter.py", line 583, in spawn_worker
    worker.init_process()
  File "/usr/local/lib/python3.6/site-packages/gunicorn/workers/base.py", line 119, in init_process
    self.load_wsgi()
  File "/usr/local/lib/python3.6/site-packages/gunicorn/workers/base.py", line 144, in load_wsgi
    self.wsgi = self.app.wsgi()
  File "/usr/local/lib/python3.6/site-packages/gunicorn/app/base.py", line 67, in wsgi
    self.callable = self.load()
  File "/usr/local/lib/python3.6/site-packages/gunicorn/app/wsgiapp.py", line 49, in load
    return self.load_wsgiapp()
  File "/usr/local/lib/python3.6/site-packages/gunicorn/app/wsgiapp.py", line 39, in load_wsgiapp
    return util.import_app(self.app_uri)
  File "/usr/local/lib/python3.6/site-packages/gunicorn/util.py", line 358, in import_app
    mod = importlib.import_module(module)
  File "/usr/lib64/python3.6/importlib/__init__.py", line 126, in import_module
    return _bootstrap._gcd_import(name[level:], package, level)
  File "<frozen importlib._bootstrap>", line 994, in _gcd_import
  File "<frozen importlib._bootstrap>", line 971, in _find_and_load
  File "<frozen importlib._bootstrap>", line 955, in _find_and_load_unlocked
  File "<frozen importlib._bootstrap>", line 665, in _load_unlocked
  File "<frozen importlib._bootstrap_external>", line 678, in exec_module
  File "<frozen importlib._bootstrap>", line 219, in _call_with_frames_removed
  File "/root/TeamRVBS/badgeuseSite.py", line 1, in <module>
    from app import app
  File "/root/TeamRVBS/app/__init__.py", line 18, in <module>
    from app import routes, models
  File "/root/TeamRVBS/app/routes.py", line 16, in <module>
    cnx = mysql.connector.connect(host='192.168.176.21',database='badgeuse',user='root',password='teamRVBS')
  File "/usr/local/lib/python3.6/site-packages/mysql/connector/__init__.py", line 179, in connect
    return MySQLConnection(*args, **kwargs)
  File "/usr/local/lib/python3.6/site-packages/mysql/connector/connection.py", line 95, in __init__
    self.connect(**kwargs)
  File "/usr/local/lib/python3.6/site-packages/mysql/connector/abstracts.py", line 716, in connect
    self._open_connection()
  File "/usr/local/lib/python3.6/site-packages/mysql/connector/connection.py", line 206, in _open_connection
    self._socket.open_connection()
  File "/usr/local/lib/python3.6/site-packages/mysql/connector/network.py", line 512, in open_connection
    errno=2003, values=(self.get_address(), _strioerror(err)))
mysql.connector.errors.InterfaceError: 2003: Can't connect to MySQL server on '192.168.176.21:3306' (111 Connection refused)
[2020-03-02 09:22:05 +0100] [2123] [INFO] Worker exiting (pid: 2123)
/root/TeamRVBS/app/pdfgen.py
True
Traceback (most recent call last):
  File "/usr/local/lib/python3.6/site-packages/gunicorn/arbiter.py", line 224, in run
    handler()
  File "/usr/local/lib/python3.6/site-packages/gunicorn/arbiter.py", line 257, in handle_term
    raise StopIteration
StopIteration

During handling of the above exception, another exception occurred:

Traceback (most recent call last):
  File "/usr/local/bin/gunicorn", line 11, in <module>
    sys.exit(run())
  File "/usr/local/lib/python3.6/site-packages/gunicorn/app/wsgiapp.py", line 58, in run
    WSGIApplication("%(prog)s [OPTIONS] [APP_MODULE]").run()
  File "/usr/local/lib/python3.6/site-packages/gunicorn/app/base.py", line 228, in run
    super().run()
  File "/usr/local/lib/python3.6/site-packages/gunicorn/app/base.py", line 72, in run
    Arbiter(self).run()
  File "/usr/local/lib/python3.6/site-packages/gunicorn/arbiter.py", line 227, in run
    self.halt()
  File "/usr/local/lib/python3.6/site-packages/gunicorn/arbiter.py", line 342, in halt
    self.stop()
  File "/usr/local/lib/python3.6/site-packages/gunicorn/arbiter.py", line 393, in stop
    time.sleep(0.1)
  File "/usr/local/lib/python3.6/site-packages/gunicorn/arbiter.py", line 242, in handle_chld
    self.reap_workers()
  File "/usr/local/lib/python3.6/site-packages/gunicorn/arbiter.py", line 525, in reap_workers
    raise HaltServer(reason, self.WORKER_BOOT_ERROR)
gunicorn.errors.HaltServer: <HaltServer 'Worker failed to boot.' 3>
